<?xml version="1.0" ?>
<robot name="custom_f450" xmlns:xacro="http://www.ros.org/wiki/xacro">

<xacro:include filename="$(find mpu6050_serial_to_imu)/urdf/materials.xacro" />
<xacro:include filename="$(find mpu6050_serial_to_imu)/urdf/custom_f450.trans" />
<xacro:include filename="$(find mpu6050_serial_to_imu)/urdf/custom_f450.gazebo" />
<link name="imu_link">
  <inertial>
    <origin xyz="0.001570974601766477 -0.0003086091973574034 0.005590903282009929" rpy="0 0 0"/>
    <mass value="0.776410855386074"/>
    <inertia ixx="0.013488" iyy="0.013488" izz="0.026937" ixy="0.0" iyz="0.0" ixz="-0.0"/>
  </inertial>
  <visual>
    <origin xyz="0 0 0" rpy="0 0 0"/>
    <geometry>
      <mesh filename="package://mpu6050_serial_to_imu/meshes/imu_link.stl" scale="0.001 0.001 0.001"/>
    </geometry>
    <material name="silver"/>
  </visual>
  <collision>
    <origin xyz="0 0 0" rpy="0 0 0"/>
    <geometry>
      <mesh filename="package://mpu6050_serial_to_imu/meshes/imu_link.stl" scale="0.001 0.001 0.001"/>
    </geometry>
  </collision>
</link>

<link name="pro1_1_1">
  <inertial>
    <origin xyz="3.4462596326667594e-07 3.9080264854567896e-07 0.01008648152911543" rpy="0 0 0"/>
    <mass value="0.014398632505168436"/>
    <inertia ixx="1e-06" iyy="0.000123" izz="0.000124" ixy="0.0" iyz="0.0" ixz="-0.0"/>
  </inertial>
  <visual>
    <origin xyz="0.293928 0.000309 -0.021504" rpy="0 0 0"/>
    <geometry>
      <mesh filename="package://mpu6050_serial_to_imu/meshes/pro1_1_1.stl" scale="0.001 0.001 0.001"/>
    </geometry>
    <material name="silver"/>
  </visual>
  <collision>
    <origin xyz="0.293928 0.000309 -0.021504" rpy="0 0 0"/>
    <geometry>
      <mesh filename="package://mpu6050_serial_to_imu/meshes/pro1_1_1.stl" scale="0.001 0.001 0.001"/>
    </geometry>
  </collision>
</link>

<link name="pro4_1_1">
  <inertial>
    <origin xyz="-2.5398240060354668e-08 -2.3917316110955156e-07 0.010086481529116575" rpy="0 0 0"/>
    <mass value="0.014398632505168407"/>
    <inertia ixx="0.000123" iyy="1e-06" izz="0.000124" ixy="-0.0" iyz="-0.0" ixz="0.0"/>
  </inertial>
  <visual>
    <origin xyz="-0.001571 0.295807 -0.021504" rpy="0 0 0"/>
    <geometry>
      <mesh filename="package://mpu6050_serial_to_imu/meshes/pro4_1_1.stl" scale="0.001 0.001 0.001"/>
    </geometry>
    <material name="silver"/>
  </visual>
  <collision>
    <origin xyz="-0.001571 0.295807 -0.021504" rpy="0 0 0"/>
    <geometry>
      <mesh filename="package://mpu6050_serial_to_imu/meshes/pro4_1_1.stl" scale="0.001 0.001 0.001"/>
    </geometry>
  </collision>
</link>

<link name="pro2_1_1">
  <inertial>
    <origin xyz="-3.954224755409186e-07 3.9080269136141906e-07 0.01008648152911638" rpy="0 0 0"/>
    <mass value="0.014398632505168596"/>
    <inertia ixx="0.000123" iyy="1e-06" izz="0.000124" ixy="-0.0" iyz="0.0" ixz="-0.0"/>
  </inertial>
  <visual>
    <origin xyz="-0.29707 0.000309 -0.021504" rpy="0 0 0"/>
    <geometry>
      <mesh filename="package://mpu6050_serial_to_imu/meshes/pro2_1_1.stl" scale="0.001 0.001 0.001"/>
    </geometry>
    <material name="silver"/>
  </visual>
  <collision>
    <origin xyz="-0.29707 0.000309 -0.021504" rpy="0 0 0"/>
    <geometry>
      <mesh filename="package://mpu6050_serial_to_imu/meshes/pro2_1_1.stl" scale="0.001 0.001 0.001"/>
    </geometry>
  </collision>
</link>

<link name="pro3_1_1">
  <inertial>
    <origin xyz="-2.53982826762221e-08 2.077840172143297e-08 0.010086481529115208" rpy="0 0 0"/>
    <mass value="0.014398632505168478"/>
    <inertia ixx="1e-06" iyy="0.000123" izz="0.000124" ixy="0.0" iyz="-0.0" ixz="-0.0"/>
  </inertial>
  <visual>
    <origin xyz="-0.001571 -0.29519 -0.021504" rpy="0 0 0"/>
    <geometry>
      <mesh filename="package://mpu6050_serial_to_imu/meshes/pro3_1_1.stl" scale="0.001 0.001 0.001"/>
    </geometry>
    <material name="silver"/>
  </visual>
  <collision>
    <origin xyz="-0.001571 -0.29519 -0.021504" rpy="0 0 0"/>
    <geometry>
      <mesh filename="package://mpu6050_serial_to_imu/meshes/pro3_1_1.stl" scale="0.001 0.001 0.001"/>
    </geometry>
  </collision>
</link>

<joint name="Rev10" type="continuous">
  <origin xyz="-0.293928 -0.000309 0.021504" rpy="0 0 0"/>
  <parent link="imu_link"/>
  <child link="pro1_1_1"/>
  <axis xyz="-0.0 0.0 1.0"/>
</joint>

<joint name="Rev11" type="continuous">
  <origin xyz="0.001571 -0.295807 0.021504" rpy="0 0 0"/>
  <parent link="imu_link"/>
  <child link="pro4_1_1"/>
  <axis xyz="-0.0 0.0 1.0"/>
</joint>

<joint name="Rev12" type="continuous">
  <origin xyz="0.29707 -0.000309 0.021504" rpy="0 0 0"/>
  <parent link="imu_link"/>
  <child link="pro2_1_1"/>
  <axis xyz="0.0 -0.0 -1.0"/>
</joint>

<joint name="Rev13" type="continuous">
  <origin xyz="0.001571 0.29519 0.021504" rpy="0 0 0"/>
  <parent link="imu_link"/>
  <child link="pro3_1_1"/>
  <axis xyz="-0.0 0.0 1.0"/>
</joint>

</robot>
